Workbook

Sheet Avancement
A1: Avancement au 02/10/2026 — rapprochement rapports équipe ↔ product backlog
A2: Sources : Rapport d'activité technique Front mobile (Youssef Feki) · Référentiel d'avancement Jira OPT-101→302 (Ahmed Jmal, commits 194e90e, 8b71bae, 8b300db, 7dd0667). « En cours » compté à 50 % dans le % pondéré (hypothèse).
A4: Par développeur
B5: J/H total | C5: J/H Done | D5: J/H en cours | E5: J/H à faire | F5: Sous-tâches Done | G5: Sous-tâches en cours | H5: % Done (J/H) | I5: % pondéré
A6: Front | B6: =SUMIFS(Backlog!$K:$K,Backlog!$I:$I,$A6,Backlog!$B:$B,"Sous-tâche") -> 102.5 | C6: =SUMIFS(Backlog!$K:$K,Backlog!$I:$I,$A6,Backlog!$B:$B,"Sous-tâche",Backlog!$Q:$Q,"Done") -> 5 | D6: =SUMIFS(Backlog!$K:$K,Backlog!$I:$I,$A6,Backlog!$B:$B,"Sous-tâche",Backlog!$Q:$Q,"In Progress") -> 2 | E6: =B6-C6-D6 -> 95.5 | F6: =COUNTIFS(Backlog!$I:$I,$A6,Backlog!$B:$B,"Sous-tâche",Backlog!$Q:$Q,"Done") -> 4 | G6: =COUNTIFS(Backlog!$I:$I,$A6,Backlog!$B:$B,"Sous-tâche",Backlog!$Q:$Q,"In Progress") -> 3 | H6: =IF(B6=0,0,C6/B6) -> 0.048780488 | I6: =IF(B6=0,0,(C6+0.5*D6)/B6) -> 0.058536585 | J6: Youssef Feki
A7: Back | B7: =SUMIFS(Backlog!$K:$K,Backlog!$I:$I,$A7,Backlog!$B:$B,"Sous-tâche") -> 125 | C7: =SUMIFS(Backlog!$K:$K,Backlog!$I:$I,$A7,Backlog!$B:$B,"Sous-tâche",Backlog!$Q:$Q,"Done") -> 19.5 | D7: =SUMIFS(Backlog!$K:$K,Backlog!$I:$I,$A7,Backlog!$B:$B,"Sous-tâche",Backlog!$Q:$Q,"In Progress") -> 12 | E7: =B7-C7-D7 -> 93.5 | F7: =COUNTIFS(Backlog!$I:$I,$A7,Backlog!$B:$B,"Sous-tâche",Backlog!$Q:$Q,"Done") -> 17 | G7: =COUNTIFS(Backlog!$I:$I,$A7,Backlog!$B:$B,"Sous-tâche",Backlog!$Q:$Q,"In Progress") -> 8 | H7: =IF(B7=0,0,C7/B7) -> 0.156 | I7: =IF(B7=0,0,(C7+0.5*D7)/B7) -> 0.204 | J7: Ahmed Jmal (Back + BDD)
A8: IA | B8: =SUMIFS(Backlog!$K:$K,Backlog!$I:$I,$A8,Backlog!$B:$B,"Sous-tâche") -> 40 | C8: =SUMIFS(Backlog!$K:$K,Backlog!$I:$I,$A8,Backlog!$B:$B,"Sous-tâche",Backlog!$Q:$Q,"Done") -> 0 | D8: =SUMIFS(Backlog!$K:$K,Backlog!$I:$I,$A8,Backlog!$B:$B,"Sous-tâche",Backlog!$Q:$Q,"In Progress") -> 0 | E8: =B8-C8-D8 -> 40 | F8: =COUNTIFS(Backlog!$I:$I,$A8,Backlog!$B:$B,"Sous-tâche",Backlog!$Q:$Q,"Done") -> 0 | G8: =COUNTIFS(Backlog!$I:$I,$A8,Backlog!$B:$B,"Sous-tâche",Backlog!$Q:$Q,"In Progress") -> 0 | H8: =IF(B8=0,0,C8/B8) -> 0 | I8: =IF(B8=0,0,(C8+0.5*D8)/B8) -> 0 | J8: Yessine Affes
A9: DevOps | B9: =SUMIFS(Backlog!$K:$K,Backlog!$I:$I,$A9,Backlog!$B:$B,"Sous-tâche") -> 42 | C9: =SUMIFS(Backlog!$K:$K,Backlog!$I:$I,$A9,Backlog!$B:$B,"Sous-tâche",Backlog!$Q:$Q,"Done") -> 0 | D9: =SUMIFS(Backlog!$K:$K,Backlog!$I:$I,$A9,Backlog!$B:$B,"Sous-tâche",Backlog!$Q:$Q,"In Progress") -> 4 | E9: =B9-C9-D9 -> 38 | F9: =COUNTIFS(Backlog!$I:$I,$A9,Backlog!$B:$B,"Sous-tâche",Backlog!$Q:$Q,"Done") -> 0 | G9: =COUNTIFS(Backlog!$I:$I,$A9,Backlog!$B:$B,"Sous-tâche",Backlog!$Q:$Q,"In Progress") -> 2 | H9: =IF(B9=0,0,C9/B9) -> 0 | I9: =IF(B9=0,0,(C9+0.5*D9)/B9) -> 0.047619048 | J9: Heni Kenoun
A11: Par sprint (sprints concernés)
B12: J/H total | C12: J/H Done | D12: J/H en cours | E12: J/H à faire | F12: Sous-tâches Done | G12: Sous-tâches en cours | H12: % Done (J/H) | I12: % pondéré
A13: S01 | B13: =SUMIFS(Backlog!$K:$K,Backlog!$N:$N,$A13,Backlog!$B:$B,"Sous-tâche") -> 25.5 | C13: =SUMIFS(Backlog!$K:$K,Backlog!$N:$N,$A13,Backlog!$B:$B,"Sous-tâche",Backlog!$Q:$Q,"Done") -> 9 | D13: =SUMIFS(Backlog!$K:$K,Backlog!$N:$N,$A13,Backlog!$B:$B,"Sous-tâche",Backlog!$Q:$Q,"In Progress") -> 10.5 | E13: =B13-C13-D13 -> 6 | F13: =COUNTIFS(Backlog!$N:$N,$A13,Backlog!$B:$B,"Sous-tâche",Backlog!$Q:$Q,"Done") -> 9 | G13: =COUNTIFS(Backlog!$N:$N,$A13,Backlog!$B:$B,"Sous-tâche",Backlog!$Q:$Q,"In Progress") -> 8 | H13: =IF(B13=0,0,C13/B13) -> 0.35294118 | I13: =IF(B13=0,0,(C13+0.5*D13)/B13) -> 0.55882353
A14: S02 | B14: =SUMIFS(Backlog!$K:$K,Backlog!$N:$N,$A14,Backlog!$B:$B,"Sous-tâche") -> 26.5 | C14: =SUMIFS(Backlog!$K:$K,Backlog!$N:$N,$A14,Backlog!$B:$B,"Sous-tâche",Backlog!$Q:$Q,"Done") -> 6.5 | D14: =SUMIFS(Backlog!$K:$K,Backlog!$N:$N,$A14,Backlog!$B:$B,"Sous-tâche",Backlog!$Q:$Q,"In Progress") -> 5.5 | E14: =B14-C14-D14 -> 14.5 | F14: =COUNTIFS(Backlog!$N:$N,$A14,Backlog!$B:$B,"Sous-tâche",Backlog!$Q:$Q,"Done") -> 5 | G14: =COUNTIFS(Backlog!$N:$N,$A14,Backlog!$B:$B,"Sous-tâche",Backlog!$Q:$Q,"In Progress") -> 3 | H14: =IF(B14=0,0,C14/B14) -> 0.24528302 | I14: =IF(B14=0,0,(C14+0.5*D14)/B14) -> 0.3490566
A15: S03 | B15: =SUMIFS(Backlog!$K:$K,Backlog!$N:$N,$A15,Backlog!$B:$B,"Sous-tâche") -> 30 | C15: =SUMIFS(Backlog!$K:$K,Backlog!$N:$N,$A15,Backlog!$B:$B,"Sous-tâche",Backlog!$Q:$Q,"Done") -> 5.5 | D15: =SUMIFS(Backlog!$K:$K,Backlog!$N:$N,$A15,Backlog!$B:$B,"Sous-tâche",Backlog!$Q:$Q,"In Progress") -> 0 | E15: =B15-C15-D15 -> 24.5 | F15: =COUNTIFS(Backlog!$N:$N,$A15,Backlog!$B:$B,"Sous-tâche",Backlog!$Q:$Q,"Done") -> 4 | G15: =COUNTIFS(Backlog!$N:$N,$A15,Backlog!$B:$B,"Sous-tâche",Backlog!$Q:$Q,"In Progress") -> 0 | H15: =IF(B15=0,0,C15/B15) -> 0.18333333 | I15: =IF(B15=0,0,(C15+0.5*D15)/B15) -> 0.18333333
A16: S04 | B16: =SUMIFS(Backlog!$K:$K,Backlog!$N:$N,$A16,Backlog!$B:$B,"Sous-tâche") -> 21.5 | C16: =SUMIFS(Backlog!$K:$K,Backlog!$N:$N,$A16,Backlog!$B:$B,"Sous-tâche",Backlog!$Q:$Q,"Done") -> 0 | D16: =SUMIFS(Backlog!$K:$K,Backlog!$N:$N,$A16,Backlog!$B:$B,"Sous-tâche",Backlog!$Q:$Q,"In Progress") -> 0 | E16: =B16-C16-D16 -> 21.5 | F16: =COUNTIFS(Backlog!$N:$N,$A16,Backlog!$B:$B,"Sous-tâche",Backlog!$Q:$Q,"Done") -> 0 | G16: =COUNTIFS(Backlog!$N:$N,$A16,Backlog!$B:$B,"Sous-tâche",Backlog!$Q:$Q,"In Progress") -> 0 | H16: =IF(B16=0,0,C16/B16) -> 0 | I16: =IF(B16=0,0,(C16+0.5*D16)/B16) -> 0
A17: S05 | B17: =SUMIFS(Backlog!$K:$K,Backlog!$N:$N,$A17,Backlog!$B:$B,"Sous-tâche") -> 22 | C17: =SUMIFS(Backlog!$K:$K,Backlog!$N:$N,$A17,Backlog!$B:$B,"Sous-tâche",Backlog!$Q:$Q,"Done") -> 1 | D17: =SUMIFS(Backlog!$K:$K,Backlog!$N:$N,$A17,Backlog!$B:$B,"Sous-tâche",Backlog!$Q:$Q,"In Progress") -> 2 | E17: =B17-C17-D17 -> 19 | F17: =COUNTIFS(Backlog!$N:$N,$A17,Backlog!$B:$B,"Sous-tâche",Backlog!$Q:$Q,"Done") -> 1 | G17: =COUNTIFS(Backlog!$N:$N,$A17,Backlog!$B:$B,"Sous-tâche",Backlog!$Q:$Q,"In Progress") -> 2 | H17: =IF(B17=0,0,C17/B17) -> 0.045454545 | I17: =IF(B17=0,0,(C17+0.5*D17)/B17) -> 0.090909091
A18: S07 | B18: =SUMIFS(Backlog!$K:$K,Backlog!$N:$N,$A18,Backlog!$B:$B,"Sous-tâche") -> 26.5 | C18: =SUMIFS(Backlog!$K:$K,Backlog!$N:$N,$A18,Backlog!$B:$B,"Sous-tâche",Backlog!$Q:$Q,"Done") -> 1 | D18: =SUMIFS(Backlog!$K:$K,Backlog!$N:$N,$A18,Backlog!$B:$B,"Sous-tâche",Backlog!$Q:$Q,"In Progress") -> 0 | E18: =B18-C18-D18 -> 25.5 | F18: =COUNTIFS(Backlog!$N:$N,$A18,Backlog!$B:$B,"Sous-tâche",Backlog!$Q:$Q,"Done") -> 1 | G18: =COUNTIFS(Backlog!$N:$N,$A18,Backlog!$B:$B,"Sous-tâche",Backlog!$Q:$Q,"In Progress") -> 0 | H18: =IF(B18=0,0,C18/B18) -> 0.037735849 | I18: =IF(B18=0,0,(C18+0.5*D18)/B18) -> 0.037735849
A19: S11 | B19: =SUMIFS(Backlog!$K:$K,Backlog!$N:$N,$A19,Backlog!$B:$B,"Sous-tâche") -> 39 | C19: =SUMIFS(Backlog!$K:$K,Backlog!$N:$N,$A19,Backlog!$B:$B,"Sous-tâche",Backlog!$Q:$Q,"Done") -> 1.5 | D19: =SUMIFS(Backlog!$K:$K,Backlog!$N:$N,$A19,Backlog!$B:$B,"Sous-tâche",Backlog!$Q:$Q,"In Progress") -> 0 | E19: =B19-C19-D19 -> 37.5 | F19: =COUNTIFS(Backlog!$N:$N,$A19,Backlog!$B:$B,"Sous-tâche",Backlog!$Q:$Q,"Done") -> 1 | G19: =COUNTIFS(Backlog!$N:$N,$A19,Backlog!$B:$B,"Sous-tâche",Backlog!$Q:$Q,"In Progress") -> 0 | H19: =IF(B19=0,0,C19/B19) -> 0.038461538 | I19: =IF(B19=0,0,(C19+0.5*D19)/B19) -> 0.038461538
A21: Par lot
B22: J/H total | C22: J/H Done | D22: J/H en cours | E22: J/H à faire | F22: Sous-tâches Done | G22: Sous-tâches en cours | H22: % Done (J/H) | I22: % pondéré
A23: Lot 1 | B23: =SUMIFS(Backlog!$K:$K,Backlog!$C:$C,$A23,Backlog!$B:$B,"Sous-tâche") -> 188 | C23: =SUMIFS(Backlog!$K:$K,Backlog!$C:$C,$A23,Backlog!$B:$B,"Sous-tâche",Backlog!$Q:$Q,"Done") -> 23 | D23: =SUMIFS(Backlog!$K:$K,Backlog!$C:$C,$A23,Backlog!$B:$B,"Sous-tâche",Backlog!$Q:$Q,"In Progress") -> 18 | E23: =B23-C23-D23 -> 147 | F23: =COUNTIFS(Backlog!$C:$C,$A23,Backlog!$B:$B,"Sous-tâche",Backlog!$Q:$Q,"Done") -> 20 | G23: =COUNTIFS(Backlog!$C:$C,$A23,Backlog!$B:$B,"Sous-tâche",Backlog!$Q:$Q,"In Progress") -> 13 | H23: =IF(B23=0,0,C23/B23) -> 0.12234043 | I23: =IF(B23=0,0,(C23+0.5*D23)/B23) -> 0.17021277
A24: Lot 2 | B24: =SUMIFS(Backlog!$K:$K,Backlog!$C:$C,$A24,Backlog!$B:$B,"Sous-tâche") -> 31 | C24: =SUMIFS(Backlog!$K:$K,Backlog!$C:$C,$A24,Backlog!$B:$B,"Sous-tâche",Backlog!$Q:$Q,"Done") -> 0 | D24: =SUMIFS(Backlog!$K:$K,Backlog!$C:$C,$A24,Backlog!$B:$B,"Sous-tâche",Backlog!$Q:$Q,"In Progress") -> 0 | E24: =B24-C24-D24 -> 31 | F24: =COUNTIFS(Backlog!$C:$C,$A24,Backlog!$B:$B,"Sous-tâche",Backlog!$Q:$Q,"Done") -> 0 | G24: =COUNTIFS(Backlog!$C:$C,$A24,Backlog!$B:$B,"Sous-tâche",Backlog!$Q:$Q,"In Progress") -> 0 | H24: =IF(B24=0,0,C24/B24) -> 0 | I24: =IF(B24=0,0,(C24+0.5*D24)/B24) -> 0
A25: Lot 3 | B25: =SUMIFS(Backlog!$K:$K,Backlog!$C:$C,$A25,Backlog!$B:$B,"Sous-tâche") -> 90.5 | C25: =SUMIFS(Backlog!$K:$K,Backlog!$C:$C,$A25,Backlog!$B:$B,"Sous-tâche",Backlog!$Q:$Q,"Done") -> 1.5 | D25: =SUMIFS(Backlog!$K:$K,Backlog!$C:$C,$A25,Backlog!$B:$B,"Sous-tâche",Backlog!$Q:$Q,"In Progress") -> 0 | E25: =B25-C25-D25 -> 89 | F25: =COUNTIFS(Backlog!$C:$C,$A25,Backlog!$B:$B,"Sous-tâche",Backlog!$Q:$Q,"Done") -> 1 | G25: =COUNTIFS(Backlog!$C:$C,$A25,Backlog!$B:$B,"Sous-tâche",Backlog!$Q:$Q,"In Progress") -> 0 | H25: =IF(B25=0,0,C25/B25) -> 0.016574586 | I25: =IF(B25=0,0,(C25+0.5*D25)/B25) -> 0.016574586
A27: Lecture
A28: • Le Back a déjà livré le cœur du module vendeurs (prévu S02-S03) et l'authentification (S01) avant la date de début planifiée (05/10) : avance sur le Back, qui est le goulot du projet.
A29: • Le Front a terminé l'essentiel de S01 (socle mobile, connexion, mot de passe oublié) ; les écrans vendeurs (US-52/53/54/55) restent à faire et dépendent d'API déjà prêtes.
A30: • Aucun livrable DevOps (Heni Kenoun) ni IA (Yessine Affes) dans les rapports : US-10 environnements Recette / Prod et US-11 CI/CD ne sont pas commencés par le DevOps.
A31: • Les 5 tâches réalisées hors backlog (≈ 4,5 J/H) ont été ajoutées à la fin de l'onglet Backlog (statut Done, source « À valider »).

Sheet Rapprochement OPT
A1: Correspondance tickets de l'équipe ↔ clés du product backlog
A3: Réf. équipe | B3: Titre (rapport équipe) | C3: SP équipe | D3: Développeur | E3: Commit | F3: Clés backlog couvertes | G3: Verdict | H3: Commentaire
A4: OPT-101 | B4: Infrastructure Docker, base de données & rôles PostgreSQL 17 | C4: 3 | D4: Ahmed Jmal | E4: 194e90e | F4: US-01-T3, US-04-T3, US-06-T1, US-05-T1 (partiel), US-10-T2 (partiel), US-40-T3 | G4: Conforme + avance | H4: Travail d'infra de dev fait par le Back ; les environnements Recette / Prod restent au DevOps.
A5: OPT-102 | B5: Authentification stateless JWT & Argon2id | C5: 5 | D5: Ahmed Jmal | E5: 194e90e | F5: US-01-T1 | G5: Conforme
A6: OPT-103 | B6: Découplage tokens / données utilisateur (/auth/me) | C6: 3 | D6: Ahmed Jmal | E6: 8b300db | F6: US-01 (nouvelle sous-tâche), US-03-T2 (partiel) | G6: Hors backlog | H6: Ajouté sous US-01.
A7: OPT-104 | B7: Réinitialisation de mot de passe en 3 étapes | C7: 5 | D7: Ahmed Jmal | E7: 8b71bae | F7: US-02-T1 | G7: Écart à valider | H7: OTP par e-mail au lieu d'un lien ; politique mot de passe 6-128 car. (faible).
A8: OPT-105 | B8: Double rate limiting & anti-énumération | C8: 3 | D8: Ahmed Jmal | E8: 194e90e | F8: US-09-T3 | G8: Écart à valider | H8: Pas de temporisation du compte après 5 échecs (critère backlog).
A9: OPT-201 | B9: Cycle de vie des statuts vendeurs | C9: 3 | D9: Ahmed Jmal | E9: 7dd0667 | F9: US-52-T1, US-52-T2 | G9: Conforme
A10: OPT-202 | B10: Affectations multi-sites & historisation | C10: 5 | D10: Ahmed Jmal | E10: 7dd0667 | F10: US-53-T1 + nouvelle sous-tâche US-53 | G10: Conforme + plus | H10: Historique daté non prévu au backlog.
A11: OPT-203 | B11: Planning ISO 7 jours & fuseaux IANA | C11: 5 | D11: Ahmed Jmal | E11: 7dd0667 | F11: US-54-T1, US-54-T2 | G11: Conforme | H11: Tranche la question ouverte : planning par affectation vendeur ↔ site.
A12: OPT-204 | B12: Contrôle d'accès dynamique temps réel | C12: 5 | D12: Ahmed Jmal | E12: 7dd0667 | F12: US-54-T1, US-52-T2, US-09-T1 (partiel) | G12: Conforme
A13: OPT-205 | B13: Onboarding vendeur : mot de passe temporaire & premier login | C13: 5 | D13: Ahmed Jmal | E13: 7dd0667 | F13: US-52 (nouvelle sous-tâche) | G13: Hors backlog | H13: Ajouté sous US-52.
A14: OPT-206 | B14: Activation PENDING / ACTIVATED & renvoi d'invitation | C14: 3 | D14: Ahmed Jmal | E14: 7dd0667 | F14: US-52 (nouvelle sous-tâche) | G14: Hors backlog | H14: Regroupé avec OPT-205.
A15: OPT-207 | B15: API REST de gestion des vendeurs | C15: 3 | D15: Ahmed Jmal | E15: 7dd0667 | F15: US-52-T1, US-03-T2 (partiel) | G15: Conforme
A16: OPT-301 | B16: Codes d'erreurs métier & exceptions HTTP | C16: 2 | D16: Ahmed Jmal | E16: 194e90e | F16: US-08 (nouvelle sous-tâche), US-08-T3 (partiel) | G16: Hors backlog | H16: Ajouté sous US-08.
A17: OPT-302 | B17: Tests E2E et unitaires, mocks SMTP | C17: 2 | D17: Ahmed Jmal | E17: 7dd0667 | F17: US-02-T3, US-55-T2 | G17: Conforme | H17: Tests SIVO / Oracle (US-07) non couverts.
A18: Front §3A | B18: Initialisation & configuration de l'app mobile | D18: Youssef Feki | E18: feature/login | F18: US-59-T1, US-59-T2 (partiel) | G18: Conforme | H18: React Native retenu (question ouverte tranchée).
A19: Front §3B-C | B19: Connexion sécurisée & gestion de session JWT | D19: Youssef Feki | E19: feature/login | F19: US-01-T2, US-09-T4 (partiel) | G19: Conforme | H19: Certificate pinning à prévoir.
A20: Front §3D | B20: Réinitialisation de mot de passe OTP | D20: Youssef Feki | E20: feature/login | F20: US-02-T2 | G20: Conforme
A21: Front §3E | B21: Navigation & écran d'accueil / profil | D21: Youssef Feki | E21: feature/login | F21: US-01 (nouvelle sous-tâche), US-03-T3 (partiel) | G21: Hors backlog | H21: Ajouté sous US-01.
A22: Front §4 | B22: Tests automatisés (8 suites, 36 tests) | D22: Youssef Feki | E22: feature/login | F22: Definition of Done | G22: Conforme

Sheet Écarts à arbitrer
A1: Écarts entre le réalisé et le backlog — décision PO requise
A3: # | B3: Écart constaté | C3: Clé backlog | D3: Recommandation PO | E3: Décision
A4: 1 | B4: Base de données applicative PostgreSQL 17 (NestJS / Prisma) alors que le CDC parle du système de production Oracle SIVO. | C4: US-04, US-05 | D4: OK si PostgreSQL = base de l'application et Oracle = système SIVO intégré par API / connecteur. À confirmer par écrit avec l'IT SIVO avant S02.
A5: 2 | B5: Mot de passe oublié par code OTP e-mail (et non lien valable 30 min). | C5: US-02 | D5: Accepter (plus adapté au mobile) et mettre à jour le critère d'acceptation.
A6: 3 | B6: Politique de mot de passe 6 à 128 caractères. | C6: US-02, US-52 | D6: Trop faible pour une application B2B : passer à 12 caractères minimum ou s'aligner sur la politique SIVO.
A7: 4 | B7: Pas de temporisation du compte après 5 échecs ; protection par rate limiting. | C7: US-09-T3 | D7: Accepter le rate limiting et ajouter un verrouillage progressif par compte, ou modifier le critère.
A8: 5 | B8: Pas de table sessions (architecture stateless) ; révocation par revérification du profil. | C8: US-01-T3, US-52-T2 | D8: Accepter : le critère « session révocable » est couvert par le contrôle à chaque requête.
A9: 6 | B9: Plages horaires définies par affectation vendeur ↔ site (et non par vendeur). | C9: US-54 | D9: Accepter : tranche la question ouverte n° 7 ; mettre à jour le critère.
A10: 7 | B10: Infra Docker de dev réalisée par le Back ; aucun livrable DevOps signalé. | C10: US-10, US-11 | D10: Confirmer avec Heni Kenoun le démarrage de US-10 (environnements) et US-11 (CI/CD), prérequis de la recette.
A11: 8 | B11: Tickets créés par l'équipe avec ses propres clés (OPT-xxx, 3 épics). | C11: Tous | D11: Ne pas créer les épics EPIC-1/2/3 : rattacher chaque OPT-xxx aux clés du backlog (voir l'onglet Rapprochement OPT) pour garder un seul référentiel.

Sheet Synthèse
A1: Plateforme Opticien ↔ ESSILOR SIVO — Backlog v2
A2: Sources : Cahier des charges v2.0 (sept. 2026, accepté par SIVO) · Devis NextStep 27082601-L1/L2/L3 du 27/08/2026 · Ajout module Vendeurs (Lot 1).
A4: Vision produit
A5: Nous aidons les opticiens clients d'ESSILOR SIVO à commander (Stock, RX, Précal), suivre, réclamer et gérer leurs équipes depuis le mobile puis le web, en remplaçant le fax et les outils hétérogènes par une plateforme unique intégrée au système Oracle — mesuré par le % de commandes et de précals passés en ligne, le taux d'erreurs de commande et la baisse des appels au support.
A7: Product Goals par lot (découpage CDC v2)
A8: Lot 1 | B8: Commandes Stock / RX / Précal digital, suivi notifié, réclamations, vendeurs avec accès par site et horaire — sur mobile, socle sécurisé intégré à Oracle.
A9: Lot 2 | B9: Favoris, tracking et décharge électronique, espace commercial du représentant.
A10: Lot 3 | B10: Recommandation et chatbot IA aux seuils de qualité / sécurité validés ; exploitation autonome par l'IT SIVO.
A11: Web | B11: Après le mobile : déclinaison web de chaque module sur le même backend (sans logique métier dupliquée).
A13: Charge par lot : couvert par le devis vs à valider
A14: Lot | B14: J/H couverts devis | C14: J/H à valider | D14: Total J/H | E14: % à valider | F14: Épics | G14: Stories | H14: Sous-tâches | I14: dont web (J/H)
A15: Lot 1 | B15: =SUMIFS(Backlog!$K:$K,Backlog!$C:$C,$A15,Backlog!$O:$O,"Devis",Backlog!$B:$B,"Sous-tâche") -> 97 | C15: =SUMIFS(Backlog!$K:$K,Backlog!$C:$C,$A15,Backlog!$O:$O,"À valider",Backlog!$B:$B,"Sous-tâche") -> 91 | D15: =B15+C15 -> 188 | E15: =IF(D15=0,0,C15/D15) -> 0.48404255 | F15: =COUNTIFS(Backlog!$C:$C,$A15,Backlog!$B:$B,"Epic") -> 11 | G15: =COUNTIFS(Backlog!$C:$C,$A15,Backlog!$B:$B,"Story") -> 44 | H15: =COUNTIFS(Backlog!$C:$C,$A15,Backlog!$B:$B,"Sous-tâche") -> 112 | I15: =SUMIFS(Backlog!$K:$K,Backlog!$C:$C,$A15,Backlog!$H:$H,"Front Web",Backlog!$B:$B,"Sous-tâche") -> 29
A16: Lot 2 | B16: =SUMIFS(Backlog!$K:$K,Backlog!$C:$C,$A16,Backlog!$O:$O,"Devis",Backlog!$B:$B,"Sous-tâche") -> 10 | C16: =SUMIFS(Backlog!$K:$K,Backlog!$C:$C,$A16,Backlog!$O:$O,"À valider",Backlog!$B:$B,"Sous-tâche") -> 21 | D16: =B16+C16 -> 31 | E16: =IF(D16=0,0,C16/D16) -> 0.67741935 | F16: =COUNTIFS(Backlog!$C:$C,$A16,Backlog!$B:$B,"Epic") -> 3 | G16: =COUNTIFS(Backlog!$C:$C,$A16,Backlog!$B:$B,"Story") -> 10 | H16: =COUNTIFS(Backlog!$C:$C,$A16,Backlog!$B:$B,"Sous-tâche") -> 25 | I16: =SUMIFS(Backlog!$K:$K,Backlog!$C:$C,$A16,Backlog!$H:$H,"Front Web",Backlog!$B:$B,"Sous-tâche") -> 6
A17: Lot 3 | B17: =SUMIFS(Backlog!$K:$K,Backlog!$C:$C,$A17,Backlog!$O:$O,"Devis",Backlog!$B:$B,"Sous-tâche") -> 83 | C17: =SUMIFS(Backlog!$K:$K,Backlog!$C:$C,$A17,Backlog!$O:$O,"À valider",Backlog!$B:$B,"Sous-tâche") -> 7.5 | D17: =B17+C17 -> 90.5 | E17: =IF(D17=0,0,C17/D17) -> 0.082872928 | F17: =COUNTIFS(Backlog!$C:$C,$A17,Backlog!$B:$B,"Epic") -> 6 | G17: =COUNTIFS(Backlog!$C:$C,$A17,Backlog!$B:$B,"Story") -> 20 | H17: =COUNTIFS(Backlog!$C:$C,$A17,Backlog!$B:$B,"Sous-tâche") -> 55 | I17: =SUMIFS(Backlog!$K:$K,Backlog!$C:$C,$A17,Backlog!$H:$H,"Front Web",Backlog!$B:$B,"Sous-tâche") -> 3.5
A18: TOTAL | B18: =SUM(B15:B17) -> 190 | C18: =SUM(C15:C17) -> 119.5 | D18: =SUM(D15:D17) -> 309.5 | E18: =IF(D18=0,0,C18/D18) -> 0.38610662 | F18: =SUM(F15:F17) -> 20 | G18: =SUM(G15:G17) -> 74 | H18: =SUM(H15:H17) -> 192 | I18: =SUM(I15:I17) -> 38.5
A19: Devis signé (réf.) | B19: 190 | C19: ="Contrôle : "&IF(B18=B19,"OK","écart "&TEXT(B18-B19,"0.0")) -> Contrôle : OK
A20: Les J/H « à valider » (module vendeurs, Précal digital, espace commercial, notifications, mobile, version web…) sont à chiffrer en avenant avec SIVO.
A22: Charge par personne et par lot (J/H)
A23: Personne | B23: Lot 1 | C23: Lot 2 | D23: Lot 3 | E23: Total | F23: Nb sous-tâches
A24: Front | B24: =SUMIFS(Backlog!$K:$K,Backlog!$C:$C,"Lot 1",Backlog!$I:$I,$A24,Backlog!$B:$B,"Sous-tâche") -> 76 | C24: =SUMIFS(Backlog!$K:$K,Backlog!$C:$C,"Lot 2",Backlog!$I:$I,$A24,Backlog!$B:$B,"Sous-tâche") -> 17 | D24: =SUMIFS(Backlog!$K:$K,Backlog!$C:$C,"Lot 3",Backlog!$I:$I,$A24,Backlog!$B:$B,"Sous-tâche") -> 9.5 | E24: =SUM(B24:D24) -> 102.5 | F24: =COUNTIFS(Backlog!$I:$I,$A24,Backlog!$B:$B,"Sous-tâche") -> 59
A25: Back | B25: =SUMIFS(Backlog!$K:$K,Backlog!$C:$C,"Lot 1",Backlog!$I:$I,$A25,Backlog!$B:$B,"Sous-tâche") -> 89.5 | C25: =SUMIFS(Backlog!$K:$K,Backlog!$C:$C,"Lot 2",Backlog!$I:$I,$A25,Backlog!$B:$B,"Sous-tâche") -> 14 | D25: =SUMIFS(Backlog!$K:$K,Backlog!$C:$C,"Lot 3",Backlog!$I:$I,$A25,Backlog!$B:$B,"Sous-tâche") -> 21.5 | E25: =SUM(B25:D25) -> 125 | F25: =COUNTIFS(Backlog!$I:$I,$A25,Backlog!$B:$B,"Sous-tâche") -> 90
A26: IA | B26: =SUMIFS(Backlog!$K:$K,Backlog!$C:$C,"Lot 1",Backlog!$I:$I,$A26,Backlog!$B:$B,"Sous-tâche") -> 0 | C26: =SUMIFS(Backlog!$K:$K,Backlog!$C:$C,"Lot 2",Backlog!$I:$I,$A26,Backlog!$B:$B,"Sous-tâche") -> 0 | D26: =SUMIFS(Backlog!$K:$K,Backlog!$C:$C,"Lot 3",Backlog!$I:$I,$A26,Backlog!$B:$B,"Sous-tâche") -> 40 | E26: =SUM(B26:D26) -> 40 | F26: =COUNTIFS(Backlog!$I:$I,$A26,Backlog!$B:$B,"Sous-tâche") -> 21
A27: DevOps | B27: =SUMIFS(Backlog!$K:$K,Backlog!$C:$C,"Lot 1",Backlog!$I:$I,$A27,Backlog!$B:$B,"Sous-tâche") -> 22.5 | C27: =SUMIFS(Backlog!$K:$K,Backlog!$C:$C,"Lot 2",Backlog!$I:$I,$A27,Backlog!$B:$B,"Sous-tâche") -> 0 | D27: =SUMIFS(Backlog!$K:$K,Backlog!$C:$C,"Lot 3",Backlog!$I:$I,$A27,Backlog!$B:$B,"Sous-tâche") -> 19.5 | E27: =SUM(B27:D27) -> 42 | F27: =COUNTIFS(Backlog!$I:$I,$A27,Backlog!$B:$B,"Sous-tâche") -> 22
A28: TOTAL | B28: =SUM(B24:B27) -> 188 | C28: =SUM(C24:C27) -> 31 | D28: =SUM(D24:D27) -> 90.5 | E28: =SUM(E24:E27) -> 309.5 | F28: =SUM(F24:F27) -> 192
A30: Risque planning & leviers
A31: Fin estimée | B31: =Sprints!O22 -> 46527
A32: Échéance CDC | B32: =Sprints!B7 -> 46444
A33: Statut | B33: =Sprints!D28 -> RETARD — voir leviers ci-dessous
A34: 1. Ajouter un 2e développeur Back ou confier une partie de la BDD à Heni Kenoun (DevOps) : le Back porte ~120 J/H seul, plus que les jours ouvrés jusqu'à fin février.
A35: 2. Livrer en février le Lot 1 mobile (S01–S07) et négocier Lots 2-3 + web en phase 2.
A36: 3. Réduire le périmètre web au strict nécessaire (back-offices SIVO déjà en web) et décaler le web opticien.
A37: 4. Passer le facteur de focus à 80 % dans l'onglet Sprints pour voir le planning réaliste.
A39: Hypothèses
A40: • Équipe : Youssef Feki (Front, mobile puis web), Ahmed Jmal (Back + BDD), Yessine Affes (IA), Heni Kenoun (DevOps).
A41: • Un seul backend / une seule API pour le mobile et le web.
A42: • Mobile d'abord (Lots 1 et 2 entièrement en mobile), puis web à partir de S09 en parallèle des sprints IA du Lot 3.
A43: • Les back-offices SIVO (réclamations, précal) sont en web dès le Lot 1 : ils servent aux équipes SIVO, pas aux opticiens.
A44: • Charge web ≈ 50 % du mobile (API et règles déjà faites) — à valider.
A45: • L'ancienne « détection IA des bons Précal » est retirée : le CDC v2 digitalise le bon (plus de papier à lire). L'aide à la saisie précal passe par le chatbot.

Sheet Sprints
A1: Plan de sprints — mobile d'abord, web ensuite — durée variable selon la capacité
A2: 1 personne par rôle : durée = charge de la personne la plus chargée (goulot) / facteur de focus + jours de cérémonies. Cellules jaunes modifiables.
A4: Date de début du projet | B4: 46300
A5: Jours de cérémonies / sprint (planning, review, rétro) | B5: 1
A6: Facteur de focus (capacité réelle / théorique) | B6: 1 | C6: Mettre 80 % pour intégrer imprévus / support.
A7: Échéance cahier des charges | B7: 46444 | C7: CDC v2 : « Échéance : février 2027 » (dernier jour ouvré retenu).
A9: Sprint | B9: Lot | C9: Nom | D9: Sprint Goal | E9: Front – Youssef Feki (J/H) | F9: dont Mobile | G9: dont Web | H9: Back+BDD – Ahmed Jmal (J/H) | I9: IA – Yessine Affes (J/H) | J9: DevOps – Heni Kenoun (J/H) | K9: Total J/H | L9: Goulot (J/H) | M9: Durée (j. ouvrés) | N9: Début | O9: Fin | P9: Stories
A10: S01 | B10: Lot 1 | C10: Fondations | D10: Connexion avec rôle sur l'app mobile en Dev ; modèle de données validé avec l'IT SIVO. | E10: =F10+G10 -> 6.5 | F10: =SUMIFS(Backlog!$K:$K,Backlog!$N:$N,$A10,Backlog!$H:$H,"Front Mobile",Backlog!$B:$B,"Sous-tâche") -> 6.5 | G10: =SUMIFS(Backlog!$K:$K,Backlog!$N:$N,$A10,Backlog!$H:$H,"Front Web",Backlog!$B:$B,"Sous-tâche") -> 0 | H10: =SUMIFS(Backlog!$K:$K,Backlog!$N:$N,$A10,Backlog!$H:$H,"Back",Backlog!$B:$B,"Sous-tâche") -> 12 | I10: =SUMIFS(Backlog!$K:$K,Backlog!$N:$N,$A10,Backlog!$H:$H,"IA",Backlog!$B:$B,"Sous-tâche") -> 0 | J10: =SUMIFS(Backlog!$K:$K,Backlog!$N:$N,$A10,Backlog!$H:$H,"DevOps",Backlog!$B:$B,"Sous-tâche") -> 7 | K10: =E10+H10+I10+J10 -> 25.5 | L10: =MAX(E10,H10,I10,J10) -> 12 | M10: =ROUNDUP(L10/$B$6,0)+$B$5 -> 13 | N10: =WORKDAY($B$4-1,1) -> 46300 | O10: =WORKDAY(N10,M10-1) -> 46316 | P10: US-59, US-01, US-02, US-03, US-04, US-10
A11: S02 | B11: Lot 1 | C11: Intégration Oracle, sécurité & comptes | D11: Lecture/écriture sécurisée dans le SI SIVO ; l'opticien configure ses sites et crée ses vendeurs ; builds mobiles distribués. | E11: =F11+G11 -> 3.5 | F11: =SUMIFS(Backlog!$K:$K,Backlog!$N:$N,$A11,Backlog!$H:$H,"Front Mobile",Backlog!$B:$B,"Sous-tâche") -> 3.5 | G11: =SUMIFS(Backlog!$K:$K,Backlog!$N:$N,$A11,Backlog!$H:$H,"Front Web",Backlog!$B:$B,"Sous-tâche") -> 0 | H11: =SUMIFS(Backlog!$K:$K,Backlog!$N:$N,$A11,Backlog!$H:$H,"Back",Backlog!$B:$B,"Sous-tâche") -> 16.5 | I11: =SUMIFS(Backlog!$K:$K,Backlog!$N:$N,$A11,Backlog!$H:$H,"IA",Backlog!$B:$B,"Sous-tâche") -> 0 | J11: =SUMIFS(Backlog!$K:$K,Backlog!$N:$N,$A11,Backlog!$H:$H,"DevOps",Backlog!$B:$B,"Sous-tâche") -> 6.5 | K11: =E11+H11+I11+J11 -> 26.5 | L11: =MAX(E11,H11,I11,J11) -> 16.5 | M11: =ROUNDUP(L11/$B$6,0)+$B$5 -> 18 | N11: =WORKDAY(O10,1) -> 46317 | O11: =WORKDAY(N11,M11-1) -> 46342 | P11: US-60, US-05, US-06, US-08, US-51, US-52
A12: S03 | B12: Lot 1 | C12: Accès vendeurs & catalogue | D12: Vendeurs limités par site, jours et heures ; recherche catalogue et commande Stock sur mobile ; CI/CD complète. | E12: =F12+G12 -> 9.5 | F12: =SUMIFS(Backlog!$K:$K,Backlog!$N:$N,$A12,Backlog!$H:$H,"Front Mobile",Backlog!$B:$B,"Sous-tâche") -> 9.5 | G12: =SUMIFS(Backlog!$K:$K,Backlog!$N:$N,$A12,Backlog!$H:$H,"Front Web",Backlog!$B:$B,"Sous-tâche") -> 0 | H12: =SUMIFS(Backlog!$K:$K,Backlog!$N:$N,$A12,Backlog!$H:$H,"Back",Backlog!$B:$B,"Sous-tâche") -> 14.5 | I12: =SUMIFS(Backlog!$K:$K,Backlog!$N:$N,$A12,Backlog!$H:$H,"IA",Backlog!$B:$B,"Sous-tâche") -> 0 | J12: =SUMIFS(Backlog!$K:$K,Backlog!$N:$N,$A12,Backlog!$H:$H,"DevOps",Backlog!$B:$B,"Sous-tâche") -> 6 | K12: =E12+H12+I12+J12 -> 30 | L12: =MAX(E12,H12,I12,J12) -> 14.5 | M12: =ROUNDUP(L12/$B$6,0)+$B$5 -> 16 | N12: =WORKDAY(O11,1) -> 46343 | O12: =WORKDAY(N12,M12-1) -> 46364 | P12: US-11, US-53, US-54, US-12, US-13
A13: S04 | B13: Lot 1 | C13: Commande RX & suivi | D13: Commande RX guidée (monture, options) transmise à SIVO et suivie ; tests d'intégration Oracle. | E13: =F13+G13 -> 7.5 | F13: =SUMIFS(Backlog!$K:$K,Backlog!$N:$N,$A13,Backlog!$H:$H,"Front Mobile",Backlog!$B:$B,"Sous-tâche") -> 7.5 | G13: =SUMIFS(Backlog!$K:$K,Backlog!$N:$N,$A13,Backlog!$H:$H,"Front Web",Backlog!$B:$B,"Sous-tâche") -> 0 | H13: =SUMIFS(Backlog!$K:$K,Backlog!$N:$N,$A13,Backlog!$H:$H,"Back",Backlog!$B:$B,"Sous-tâche") -> 14 | I13: =SUMIFS(Backlog!$K:$K,Backlog!$N:$N,$A13,Backlog!$H:$H,"IA",Backlog!$B:$B,"Sous-tâche") -> 0 | J13: =SUMIFS(Backlog!$K:$K,Backlog!$N:$N,$A13,Backlog!$H:$H,"DevOps",Backlog!$B:$B,"Sous-tâche") -> 0 | K13: =E13+H13+I13+J13 -> 21.5 | L13: =MAX(E13,H13,I13,J13) -> 14 | M13: =ROUNDUP(L13/$B$6,0)+$B$5 -> 15 | N13: =WORKDAY(O12,1) -> 46365 | O13: =WORKDAY(N13,M13-1) -> 46385 | P13: US-07, US-14, US-15, US-45, US-16, US-17
A14: S05 | B14: Lot 1 | C14: Précal digital (saisie) | D14: Un opticien envoie un bon précal complet, contrôlé et horodaté depuis le mobile ; audit des actions sensibles. | E14: =F14+G14 -> 9.5 | F14: =SUMIFS(Backlog!$K:$K,Backlog!$N:$N,$A14,Backlog!$H:$H,"Front Mobile",Backlog!$B:$B,"Sous-tâche") -> 9.5 | G14: =SUMIFS(Backlog!$K:$K,Backlog!$N:$N,$A14,Backlog!$H:$H,"Front Web",Backlog!$B:$B,"Sous-tâche") -> 0 | H14: =SUMIFS(Backlog!$K:$K,Backlog!$N:$N,$A14,Backlog!$H:$H,"Back",Backlog!$B:$B,"Sous-tâche") -> 12.5 | I14: =SUMIFS(Backlog!$K:$K,Backlog!$N:$N,$A14,Backlog!$H:$H,"IA",Backlog!$B:$B,"Sous-tâche") -> 0 | J14: =SUMIFS(Backlog!$K:$K,Backlog!$N:$N,$A14,Backlog!$H:$H,"DevOps",Backlog!$B:$B,"Sous-tâche") -> 0 | K14: =E14+H14+I14+J14 -> 22 | L14: =MAX(E14,H14,I14,J14) -> 12.5 | M14: =ROUNDUP(L14/$B$6,0)+$B$5 -> 14 | N14: =WORKDAY(O13,1) -> 46386 | O14: =WORKDAY(N14,M14-1) -> 46405 | P14: US-09, US-20, US-21, US-47
A15: S06 | B15: Lot 1 | C15: Précal SIVO, notifications & réclamations | D15: SIVO traite le précal en back-office ; l'opticien est notifié et déclare une réclamation. | E15: =F15+G15 -> 9 | F15: =SUMIFS(Backlog!$K:$K,Backlog!$N:$N,$A15,Backlog!$H:$H,"Front Mobile",Backlog!$B:$B,"Sous-tâche") -> 6 | G15: =SUMIFS(Backlog!$K:$K,Backlog!$N:$N,$A15,Backlog!$H:$H,"Front Web",Backlog!$B:$B,"Sous-tâche") -> 3 | H15: =SUMIFS(Backlog!$K:$K,Backlog!$N:$N,$A15,Backlog!$H:$H,"Back",Backlog!$B:$B,"Sous-tâche") -> 12 | I15: =SUMIFS(Backlog!$K:$K,Backlog!$N:$N,$A15,Backlog!$H:$H,"IA",Backlog!$B:$B,"Sous-tâche") -> 2.5 | J15: =SUMIFS(Backlog!$K:$K,Backlog!$N:$N,$A15,Backlog!$H:$H,"DevOps",Backlog!$B:$B,"Sous-tâche") -> 0.5 | K15: =E15+H15+I15+J15 -> 24 | L15: =MAX(E15,H15,I15,J15) -> 12 | M15: =ROUNDUP(L15/$B$6,0)+$B$5 -> 13 | N15: =WORKDAY(O14,1) -> 46406 | O15: =WORKDAY(N15,M15-1) -> 46422 | P15: US-48, US-49, US-46, US-24, US-28
A16: S07 | B16: Lot 1 | C16: Réclamations, permissions vendeurs & stores | D16: Réclamation traitée jusqu'à la clôture ; permissions vendeurs ; app publiée. Recette mobile Lot 1. | E16: =F16+G16 -> 7.5 | F16: =SUMIFS(Backlog!$K:$K,Backlog!$N:$N,$A16,Backlog!$H:$H,"Front Mobile",Backlog!$B:$B,"Sous-tâche") -> 4.5 | G16: =SUMIFS(Backlog!$K:$K,Backlog!$N:$N,$A16,Backlog!$H:$H,"Front Web",Backlog!$B:$B,"Sous-tâche") -> 3 | H16: =SUMIFS(Backlog!$K:$K,Backlog!$N:$N,$A16,Backlog!$H:$H,"Back",Backlog!$B:$B,"Sous-tâche") -> 12 | I16: =SUMIFS(Backlog!$K:$K,Backlog!$N:$N,$A16,Backlog!$H:$H,"IA",Backlog!$B:$B,"Sous-tâche") -> 5.5 | J16: =SUMIFS(Backlog!$K:$K,Backlog!$N:$N,$A16,Backlog!$H:$H,"DevOps",Backlog!$B:$B,"Sous-tâche") -> 1.5 | K16: =E16+H16+I16+J16 -> 26.5 | L16: =MAX(E16,H16,I16,J16) -> 12 | M16: =ROUNDUP(L16/$B$6,0)+$B$5 -> 13 | N16: =WORKDAY(O15,1) -> 46423 | O16: =WORKDAY(N16,M16-1) -> 46441 | P16: US-61, US-55, US-25, US-26, US-27, US-31
A17: S08 | B17: Lot 2 | C17: Favoris, tracking & espace commercial | D17: Commande depuis favoris, décharge électronique, représentant qui commande pour son client. Recette mobile Lot 2. | E17: =F17+G17 -> 11 | F17: =SUMIFS(Backlog!$K:$K,Backlog!$N:$N,$A17,Backlog!$H:$H,"Front Mobile",Backlog!$B:$B,"Sous-tâche") -> 11 | G17: =SUMIFS(Backlog!$K:$K,Backlog!$N:$N,$A17,Backlog!$H:$H,"Front Web",Backlog!$B:$B,"Sous-tâche") -> 0 | H17: =SUMIFS(Backlog!$K:$K,Backlog!$N:$N,$A17,Backlog!$H:$H,"Back",Backlog!$B:$B,"Sous-tâche") -> 14 | I17: =SUMIFS(Backlog!$K:$K,Backlog!$N:$N,$A17,Backlog!$H:$H,"IA",Backlog!$B:$B,"Sous-tâche") -> 0 | J17: =SUMIFS(Backlog!$K:$K,Backlog!$N:$N,$A17,Backlog!$H:$H,"DevOps",Backlog!$B:$B,"Sous-tâche") -> 0 | K17: =E17+H17+I17+J17 -> 25 | L17: =MAX(E17,H17,I17,J17) -> 14 | M17: =ROUNDUP(L17/$B$6,0)+$B$5 -> 15 | N17: =WORKDAY(O16,1) -> 46442 | O17: =WORKDAY(N17,M17-1) -> 46462 | P17: US-18, US-19, US-22, US-23, US-56, US-57, US-58
A18: S09 | B18: Lot 3 + Web | C18: Recommandation & socle web | D18: Verre recommandé justifié ; le web démarre : connexion, rôles, vendeurs. | E18: =F18+G18 -> 8.5 | F18: =SUMIFS(Backlog!$K:$K,Backlog!$N:$N,$A18,Backlog!$H:$H,"Front Mobile",Backlog!$B:$B,"Sous-tâche") -> 1.5 | G18: =SUMIFS(Backlog!$K:$K,Backlog!$N:$N,$A18,Backlog!$H:$H,"Front Web",Backlog!$B:$B,"Sous-tâche") -> 7 | H18: =SUMIFS(Backlog!$K:$K,Backlog!$N:$N,$A18,Backlog!$H:$H,"Back",Backlog!$B:$B,"Sous-tâche") -> 2 | I18: =SUMIFS(Backlog!$K:$K,Backlog!$N:$N,$A18,Backlog!$H:$H,"IA",Backlog!$B:$B,"Sous-tâche") -> 6.5 | J18: =SUMIFS(Backlog!$K:$K,Backlog!$N:$N,$A18,Backlog!$H:$H,"DevOps",Backlog!$B:$B,"Sous-tâche") -> 1 | K18: =E18+H18+I18+J18 -> 18 | L18: =MAX(E18,H18,I18,J18) -> 8.5 | M18: =ROUNDUP(L18/$B$6,0)+$B$5 -> 10 | N18: =WORKDAY(O17,1) -> 46463 | O18: =WORKDAY(N18,M18-1) -> 46476 | P18: US-W00, US-W01, US-W02, US-W03, US-29, US-30
A19: S10 | B19: Lot 3 + Web | C19: Chatbot IA & commande web | D19: Chatbot complet sur mobile ; commande Stock/RX sur le web. | E19: =F19+G19 -> 11 | F19: =SUMIFS(Backlog!$K:$K,Backlog!$N:$N,$A19,Backlog!$H:$H,"Front Mobile",Backlog!$B:$B,"Sous-tâche") -> 4.5 | G19: =SUMIFS(Backlog!$K:$K,Backlog!$N:$N,$A19,Backlog!$H:$H,"Front Web",Backlog!$B:$B,"Sous-tâche") -> 6.5 | H19: =SUMIFS(Backlog!$K:$K,Backlog!$N:$N,$A19,Backlog!$H:$H,"Back",Backlog!$B:$B,"Sous-tâche") -> 7.5 | I19: =SUMIFS(Backlog!$K:$K,Backlog!$N:$N,$A19,Backlog!$H:$H,"IA",Backlog!$B:$B,"Sous-tâche") -> 11 | J19: =SUMIFS(Backlog!$K:$K,Backlog!$N:$N,$A19,Backlog!$H:$H,"DevOps",Backlog!$B:$B,"Sous-tâche") -> 0 | K19: =E19+H19+I19+J19 -> 29.5 | L19: =MAX(E19,H19,I19,J19) -> 11 | M19: =ROUNDUP(L19/$B$6,0)+$B$5 -> 12 | N19: =WORKDAY(O18,1) -> 46477 | O19: =WORKDAY(N19,M19-1) -> 46492 | P19: US-W04, US-32, US-33, US-34, US-35, US-50
A20: S11 | B20: Lot 3 + Web | C20: Qualité IA, supervision & web Lot 1 | D20: Seuils IA atteints, tests d'injection passés, supervision active ; Lot 1 complet sur le web. | E20: =F20+G20 -> 10 | F20: =SUMIFS(Backlog!$K:$K,Backlog!$N:$N,$A20,Backlog!$H:$H,"Front Mobile",Backlog!$B:$B,"Sous-tâche") -> 0 | G20: =SUMIFS(Backlog!$K:$K,Backlog!$N:$N,$A20,Backlog!$H:$H,"Front Web",Backlog!$B:$B,"Sous-tâche") -> 10 | H20: =SUMIFS(Backlog!$K:$K,Backlog!$N:$N,$A20,Backlog!$H:$H,"Back",Backlog!$B:$B,"Sous-tâche") -> 6.5 | I20: =SUMIFS(Backlog!$K:$K,Backlog!$N:$N,$A20,Backlog!$H:$H,"IA",Backlog!$B:$B,"Sous-tâche") -> 12.5 | J20: =SUMIFS(Backlog!$K:$K,Backlog!$N:$N,$A20,Backlog!$H:$H,"DevOps",Backlog!$B:$B,"Sous-tâche") -> 10 | K20: =E20+H20+I20+J20 -> 39 | L20: =MAX(E20,H20,I20,J20) -> 12.5 | M20: =ROUNDUP(L20/$B$6,0)+$B$5 -> 14 | N20: =WORKDAY(O19,1) -> 46493 | O20: =WORKDAY(N20,M20-1) -> 46512 | P20: US-W05, US-W06, US-W07, US-36, US-37, US-38, US-39, US-40
A21: S12 | B21: Lots 2-3 + Web | C21: Web Lots 2-3, sauvegarde & transfert | D21: Web complet ; restauration testée ; IT SIVO autonome. Recette finale. | E21: =F21+G21 -> 9 | F21: =SUMIFS(Backlog!$K:$K,Backlog!$N:$N,$A21,Backlog!$H:$H,"Front Mobile",Backlog!$B:$B,"Sous-tâche") -> 0 | G21: =SUMIFS(Backlog!$K:$K,Backlog!$N:$N,$A21,Backlog!$H:$H,"Front Web",Backlog!$B:$B,"Sous-tâche") -> 9 | H21: =SUMIFS(Backlog!$K:$K,Backlog!$N:$N,$A21,Backlog!$H:$H,"Back",Backlog!$B:$B,"Sous-tâche") -> 1.5 | I21: =SUMIFS(Backlog!$K:$K,Backlog!$N:$N,$A21,Backlog!$H:$H,"IA",Backlog!$B:$B,"Sous-tâche") -> 2 | J21: =SUMIFS(Backlog!$K:$K,Backlog!$N:$N,$A21,Backlog!$H:$H,"DevOps",Backlog!$B:$B,"Sous-tâche") -> 9.5 | K21: =E21+H21+I21+J21 -> 22 | L21: =MAX(E21,H21,I21,J21) -> 9.5 | M21: =ROUNDUP(L21/$B$6,0)+$B$5 -> 11 | N21: =WORKDAY(O20,1) -> 46513 | O21: =WORKDAY(N21,M21-1) -> 46527 | P21: US-W08, US-W09, US-W10, US-W11, US-W12, US-41, US-42, US-43, US-44
A22: TOTAL | E22: =SUM(E10:E21) -> 102.5 | F22: =SUM(F10:F21) -> 64 | G22: =SUM(G10:G21) -> 38.5 | H22: =SUM(H10:H21) -> 125 | I22: =SUM(I10:I21) -> 40 | J22: =SUM(J10:J21) -> 42 | K22: =SUM(K10:K21) -> 309.5 | L22: =SUM(L10:L21) -> 149 | M22: =SUM(M10:M21) -> 164 | N22: =N10 -> 46300 | O22: =O21 -> 46527
A24: Contrôle de l'échéance
A25: Fin estimée du projet | D25: =O22 -> 46527
A26: Échéance CDC | D26: =$B$7 -> 46444
A27: Écart (jours ouvrés, + = retard) | D27: =NETWORKDAYS($B$7,O22)-1 -> 59
A28: Statut | D28: =IF(O22<=$B$7,"Dans les temps","RETARD — voir leviers ci-dessous") -> RETARD — voir leviers ci-dessous
A30: Taux d'occupation par personne (charge / jours ouvrés hors cérémonies)
E31: Youssef Feki (Front) | F31: Ahmed Jmal (Back) | G31: Yessine Affes (IA) | H31: Heni Kenoun (DevOps)
E32: =E22/(M22-$B$5*12) -> 0.67434211 | F32: =H22/(M22-$B$5*12) -> 0.82236842 | G32: =I22/(M22-$B$5*12) -> 0.26315789 | H32: =J22/(M22-$B$5*12) -> 0.27631579
A33: Back = personne la plus chargée (~121 J/H) : il porte le backend ET la base de données ; il est le goulot des 8 premiers sprints.

Sheet Backlog
A1: Clé | B1: Type | C1: Lot | D1: Épic | E1: Parent | F1: Résumé | G1: User story & critères d'acceptation | H1: Rôle | I1: Personne (équipe) | J1: Assigné | K1: Estimation J/H | L1: Story points | M1: Priorité | N1: Sprint | O1: Source charge | P1: Dépendances | Q1: Statut | R1: Réf. devis / CDC | S1: Réf. équipe (Jira OPT / rapport) | T1: Constat du rapprochement
A2: E20 | B2: Epic | C2: Lot 1 | D2: E20 | F2: Socle application mobile (iOS / Android) | G2: Objectif : Disposer d'une application mobile iOS/Android branchée sur le backend unique. Réf. : Hors devis — CDC v2 multi-canal (avenant) | K2: =SUMIFS($K:$K,$D:$D,A2,$B:$B,"Sous-tâche") -> 13 | L2: =SUMIFS($L:$L,$D:$D,A2,$B:$B,"Story") -> 26 | M2: Highest | P2: E05 | Q2: =IF(COUNTIFS($D:$D,A2,$B:$B,"Sous-tâche")=0,"To Do",IF(COUNTIFS($D:$D,A2,$B:$B,"Sous-tâche",$Q:$Q,"Done")=COUNTIFS($D:$D,A2,$B:$B,"Sous-tâche"),"Done",IF(COUNTIFS($D:$D,A2,$B:$B,"Sous-tâche",$Q:$Q,"To Do")=COUNTIFS($D:$D,A2,$B:$B,"Sous-tâche"),"To Do","In Progress"))) -> In Progress | R2: Hors devis — CDC v2 multi-canal (avenant)
A3: US-59 | B3: Story | C3: Lot 1 | D3: E20 | E3: E20 | F3: Initialisation de l'application mobile | G3: En tant qu'équipe projet, je veux une base d'application mobile partagée iOS / Android, afin de développer chaque écran une seule fois. Critères d'acceptation : • Projet cross-platform (React Native ou Flutter — à valider), navigation, thème / design system. • Client API unique partagé avec le futur front web. | H3: Front Mobile | I3: Front | J3: Youssef Feki | K3: =SUMIFS($K:$K,$E:$E,A3,$B:$B,"Sous-tâche") -> 4 | L3: 8 | M3: Highest | N3: S01 | O3: À valider | P3: E05 | Q3: =IF(COUNTIFS($E:$E,A3,$B:$B,"Sous-tâche")=0,"To Do",IF(COUNTIFS($E:$E,A3,$B:$B,"Sous-tâche",$Q:$Q,"Done")=COUNTIFS($E:$E,A3,$B:$B,"Sous-tâche"),"Done",IF(COUNTIFS($E:$E,A3,$B:$B,"Sous-tâche",$Q:$Q,"To Do")=COUNTIFS($E:$E,A3,$B:$B,"Sous-tâche"),"To Do","In Progress"))) -> In Progress | R3: Hors devis — CDC v2 multi-canal (avenant)
A4: US-59-T1 | B4: Sous-tâche | C4: Lot 1 | D4: E20 | E4: US-59 | F4: [Front Mobile] Initialisation projet, navigation, design system | H4: Front Mobile | I4: Front | J4: Youssef Feki | K4: 3 | M4: Highest | N4: S01 | O4: À valider | Q4: Done | R4: Hors devis — CDC v2 multi-canal (avenant) | S4: Rapport Front §2-3A | T4: React Native 0.87 + TypeScript, Clean Architecture, thème clair/sombre, police Manrope, charte OptiVo.
A5: US-59-T2 | B5: Sous-tâche | C5: Lot 1 | D5: E20 | E5: US-59 | F5: [Front Mobile] Client API typé + gestion des erreurs et du mode hors ligne | H5: Front Mobile | I5: Front | J5: Youssef Feki | K5: 1 | M5: Highest | N5: S01 | O5: À valider | Q5: In Progress | R5: Hors devis — CDC v2 multi-canal (avenant) | S5: Rapport Front §3A-3C | T5: Client API + validation env faits ; mode hors ligne prévu (prochaine étape 02).
A6: US-60 | B6: Story | C6: Lot 1 | D6: E20 | E6: E20 | F6: Build et distribution mobile | G6: En tant que PO, je veux recevoir chaque version mobile sur mon téléphone, afin de recetter sur appareil réel. Critères d'acceptation : • Build iOS et Android automatiques dans la CI. • Distribution de recette (TestFlight / Play internal testing). | H6: DevOps | I6: DevOps | J6: Heni Kenoun | K6: =SUMIFS($K:$K,$E:$E,A6,$B:$B,"Sous-tâche") -> 3 | L6: 5 | M6: High | N6: S02 | O6: À valider | P6: E05 | Q6: =IF(COUNTIFS($E:$E,A6,$B:$B,"Sous-tâche")=0,"To Do",IF(COUNTIFS($E:$E,A6,$B:$B,"Sous-tâche",$Q:$Q,"Done")=COUNTIFS($E:$E,A6,$B:$B,"Sous-tâche"),"Done",IF(COUNTIFS($E:$E,A6,$B:$B,"Sous-tâche",$Q:$Q,"To Do")=COUNTIFS($E:$E,A6,$B:$B,"Sous-tâche"),"To Do","In Progress"))) -> To Do | R6: Hors devis — CDC v2 multi-canal (avenant)
A7: US-60-T1 | B7: Sous-tâche | C7: Lot 1 | D7: E20 | E7: US-60 | F7: [DevOps] Pipeline de build mobile + signature des applications | H7: DevOps | I7: DevOps | J7: Heni Kenoun | K7: 2 | M7: High | N7: S02 | O7: À valider | Q7: To Do | R7: Hors devis — CDC v2 multi-canal (avenant)
A8: US-60-T2 | B8: Sous-tâche | C8: Lot 1 | D8: E20 | E8: US-60 | F8: [DevOps] Distribution TestFlight / Google Play (test interne) | H8: DevOps | I8: DevOps | J8: Heni Kenoun | K8: 1 | M8: High | N8: S02 | O8: À valider | Q8: To Do | R8: Hors devis — CDC v2 multi-canal (avenant)
A9: US-61 | B9: Story | C9: Lot 1 | D9: E20 | E9: E20 | F9: Publication sur les stores | G9: En tant qu'opticien, je veux télécharger l'application sur l'App Store et Google Play, afin de l'utiliser sur mon téléphone. Critères d'acceptation : • Fiches store, captures, politique de confidentialité prêtes. • Application validée par Apple et Google. | H9: Front Mobile, DevOps | I9: Front, DevOps | J9: Heni Kenoun | K9: =SUMIFS($K:$K,$E:$E,A9,$B:$B,"Sous-tâche") -> 2.5 | L9: 5 | M9: High | N9: S07 | O9: À valider | P9: E05 | Q9: =IF(COUNTIFS($E:$E,A9,$B:$B,"Sous-tâche")=0,"To Do",IF(COUNTIFS($E:$E,A9,$B:$B,"Sous-tâche",$Q:$Q,"Done")=COUNTIFS($E:$E,A9,$B:$B,"Sous-tâche"),"Done",IF(COUNTIFS($E:$E,A9,$B:$B,"Sous-tâche",$Q:$Q,"To Do")=COUNTIFS($E:$E,A9,$B:$B,"Sous-tâche"),"To Do","In Progress"))) -> To Do | R9: Hors devis — CDC v2 multi-canal (avenant)
A10: US-61-T1 | B10: Sous-tâche | C10: Lot 1 | D10: E20 | E10: US-61 | F10: [DevOps] Comptes développeur, fiches store, soumission | H10: DevOps | I10: DevOps | J10: Heni Kenoun | K10: 1.5 | M10: High | N10: S07 | O10: À valider | Q10: To Do | R10: Hors devis — CDC v2 multi-canal (avenant)
A11: US-61-T2 | B11: Sous-tâche | C11: Lot 1 | D11: E20 | E11: US-61 | F11: [Front Mobile] Ajustements de conformité store (permissions, écrans) | H11: Front Mobile | I11: Front | J11: Youssef Feki | K11: 1 | M11: High | N11: S07 | O11: À valider | Q11: To Do | R11: Hors devis — CDC v2 multi-canal (avenant)
A12: US-W00 | B12: Story | C12: Lot 1 | D12: E20 | E12: E20 | F12: Socle front web (réutilise le client API mobile) | G12: En tant qu'équipe projet, je veux une base web qui réutilise le client API et le design system du mobile, afin de décliner les écrans rapidement. Critères d'acceptation : • Projet web initialisé, responsive, branché sur le même backend. • Build web intégré au pipeline. | H12: Front Web, DevOps | I12: Front, DevOps | J12: Youssef Feki | K12: =SUMIFS($K:$K,$E:$E,A12,$B:$B,"Sous-tâche") -> 3.5 | L12: 8 | M12: High | N12: S09 | O12: À valider | P12: E05 | Q12: =IF(COUNTIFS($E:$E,A12,$B:$B,"Sous-tâche")=0,"To Do",IF(COUNTIFS($E:$E,A12,$B:$B,"Sous-tâche",$Q:$Q,"Done")=COUNTIFS($E:$E,A12,$B:$B,"Sous-tâche"),"Done",IF(COUNTIFS($E:$E,A12,$B:$B,"Sous-tâche",$Q:$Q,"To Do")=COUNTIFS($E:$E,A12,$B:$B,"Sous-tâche"),"To Do","In Progress"))) -> To Do | R12: Hors devis — CDC v2 multi-canal (avenant)
A13: US-W00-T1 | B13: Sous-tâche | C13: Lot 1 | D13: E20 | E13: US-W00 | F13: [Front Web] Initialisation projet web, layout responsive, design system partagé | H13: Front Web | I13: Front | J13: Youssef Feki | K13: 2 | M13: High | N13: S09 | O13: À valider | Q13: To Do | R13: Hors devis — CDC v2 multi-canal (avenant)
A14: US-W00-T2 | B14: Sous-tâche | C14: Lot 1 | D14: E20 | E14: US-W00 | F14: [Front Web] Intégration du build web au pipeline | H14: Front Web | I14: Front | J14: Youssef Feki | K14: 0.5 | M14: High | N14: S09 | O14: À valider | Q14: To Do | R14: Hors devis — CDC v2 multi-canal (avenant)
A15: US-W00-T3 | B15: Sous-tâche | C15: Lot 1 | D15: E20 | E15: US-W00 | F15: [DevOps] Hébergement et déploiement du front web | H15: DevOps | I15: DevOps | J15: Heni Kenoun | K15: 1 | M15: High | N15: S09 | O15: À valider | Q15: To Do | R15: Hors devis — CDC v2 multi-canal (avenant)
A16: E01 | B16: Epic | C16: Lot 1 | D16: E01 | F16: Authentification | G16: Objectif : Permettre aux utilisateurs d'accéder à l'application de manière sécurisée. Réf. : L1 – Socle technique / Tâche 1 | K16: =SUMIFS($K:$K,$D:$D,A16,$B:$B,"Sous-tâche") -> 7 | L16: =SUMIFS($L:$L,$D:$D,A16,$B:$B,"Story") -> 10 | M16: Highest | P16: Choix du mode d'authentification (comptes locaux / annuaire SIVO / SSO) | Q16: =IF(COUNTIFS($D:$D,A16,$B:$B,"Sous-tâche")=0,"To Do",IF(COUNTIFS($D:$D,A16,$B:$B,"Sous-tâche",$Q:$Q,"Done")=COUNTIFS($D:$D,A16,$B:$B,"Sous-tâche"),"Done",IF(COUNTIFS($D:$D,A16,$B:$B,"Sous-tâche",$Q:$Q,"To Do")=COUNTIFS($D:$D,A16,$B:$B,"Sous-tâche"),"To Do","In Progress"))) -> In Progress | R16: L1 – Socle technique / Tâche 1
A17: US-01 | B17: Story | C17: Lot 1 | D17: E01 | E17: E01 | F17: Connexion / déconnexion sécurisée | G17: En tant qu'opticien, je veux me connecter et me déconnecter de façon sécurisée, afin d'accéder à mon espace de commande. Critères d'acceptation : • Étant donné un compte actif, quand je saisis des identifiants valides, alors j'accède au tableau de bord en < 2 s. • Étant donné des identifiants invalides, alors un message générique s'affiche (sans préciser le champ en erreur). • La session expire après inactivité (durée à valider) et le jeton de rafraîchissement est révocable. • Après déconnexion, le bouton Retour du navigateur ne réaffiche aucune donnée. | H17: Front Mobile, Back | I17: Front, Back | J17: Ahmed Jmal | K17: =SUMIFS($K:$K,$E:$E,A17,$B:$B,"Sous-tâche") -> 4 | L17: 5 | M17: Highest | N17: S01 | O17: Devis | P17: Choix du mode d'authentification (comptes locaux / annuaire SIVO / SSO) | Q17: =IF(COUNTIFS($E:$E,A17,$B:$B,"Sous-tâche")=0,"To Do",IF(COUNTIFS($E:$E,A17,$B:$B,"Sous-tâche",$Q:$Q,"Done")=COUNTIFS($E:$E,A17,$B:$B,"Sous-tâche"),"Done",IF(COUNTIFS($E:$E,A17,$B:$B,"Sous-tâche",$Q:$Q,"To Do")=COUNTIFS($E:$E,A17,$B:$B,"Sous-tâche"),"To Do","In Progress"))) -> Done | R17: L1 – Socle technique / Tâche 1
A18: US-01-T1 | B18: Sous-tâche | C18: Lot 1 | D18: E01 | E18: US-01 | F18: [Back] API login / logout / refresh token (JWT) + expiration de session | H18: Back | I18: Back | J18: Ahmed Jmal | K18: 1.5 | M18: Highest | N18: S01 | O18: Devis | Q18: Done | R18: L1 – Socle technique / Tâche 1 | S18: OPT-102, OPT-103 | T18: Login / refresh / logout JWT stateless, Argon2id, profil revérifié à chaque refresh.
A19: US-01-T2 | B19: Sous-tâche | C19: Lot 1 | D19: E01 | E19: US-01 | F19: [Front Mobile] Écran de connexion mobile + gestion du jeton et redirections | H19: Front Mobile | I19: Front | J19: Youssef Feki | K19: 1 | M19: Highest | N19: S01 | O19: Devis | Q19: Done | R19: L1 – Socle technique / Tâche 1 | S19: Rapport Front §3B-3C | T19: LoginScreen, validation temps réel, auto-refresh JWT, reconnexion transparente, restauration de session.
A20: US-01-T3 | B20: Sous-tâche | C20: Lot 1 | D20: E01 | E20: US-01 | F20: [Back] Tables users / sessions / refresh_tokens | H20: Back | I20: Back | J20: Ahmed Jmal | K20: 0.5 | M20: Highest | N20: S01 | O20: Devis | Q20: Done | R20: L1 – Socle technique / Tâche 1 | S20: OPT-101, OPT-102 | T20: Modèle Prisma users / profils. Pas de table sessions (choix stateless, assumé).
A21: US-02 | B21: Story | C21: Lot 1 | D21: E01 | E21: E01 | F21: Mot de passe oublié & réinitialisation | G21: En tant qu'opticien, je veux réinitialiser mon mot de passe, afin de récupérer mon compte sans appeler le support. Critères d'acceptation : • Quand je demande une réinitialisation, alors je reçois un lien à usage unique valable 30 min. • Le nouveau mot de passe respecte la politique SIVO (longueur, complexité). • La réponse est identique que l'e-mail existe ou non (pas d'énumération de comptes). | H21: Front Mobile, Back | I21: Front, Back | J21: Ahmed Jmal | K21: =SUMIFS($K:$K,$E:$E,A21,$B:$B,"Sous-tâche") -> 2 | L21: 3 | M21: High | N21: S01 | O21: Devis | P21: Choix du mode d'authentification (comptes locaux / annuaire SIVO / SSO) | Q21: =IF(COUNTIFS($E:$E,A21,$B:$B,"Sous-tâche")=0,"To Do",IF(COUNTIFS($E:$E,A21,$B:$B,"Sous-tâche",$Q:$Q,"Done")=COUNTIFS($E:$E,A21,$B:$B,"Sous-tâche"),"Done",IF(COUNTIFS($E:$E,A21,$B:$B,"Sous-tâche",$Q:$Q,"To Do")=COUNTIFS($E:$E,A21,$B:$B,"Sous-tâche"),"To Do","In Progress"))) -> Done | R21: L1 – Socle technique / Tâche 1
A22: US-02-T1 | B22: Sous-tâche | C22: Lot 1 | D22: E01 | E22: US-02 | F22: [Back] Flux reset : génération jeton, envoi e-mail, validation | H22: Back | I22: Back | J22: Ahmed Jmal | K22: 1 | M22: High | N22: S01 | O22: Devis | Q22: Done | R22: L1 – Socle technique / Tâche 1 | S22: OPT-104 | T22: Écart vs critère : code OTP par e-mail au lieu d'un lien 30 min → critère à mettre à jour.
A23: US-02-T2 | B23: Sous-tâche | C23: Lot 1 | D23: E01 | E23: US-02 | F23: [Front Mobile] Écrans mot de passe oublié / nouveau mot de passe | H23: Front Mobile | I23: Front | J23: Youssef Feki | K23: 0.5 | M23: High | N23: S01 | O23: Devis | Q23: Done | R23: L1 – Socle technique / Tâche 1 | S23: Rapport Front §3D | T23: Flux 4 étapes avec OTP 6 chiffres (BottomSheet).
A24: US-02-T3 | B24: Sous-tâche | C24: Lot 1 | D24: E01 | E24: US-02 | F24: [Back] Tests automatisés du module d'authentification | H24: Back | I24: Back | J24: Ahmed Jmal | K24: 0.5 | M24: High | N24: S01 | O24: Devis | Q24: Done | R24: L1 – Socle technique / Tâche 1 | S24: OPT-302 | T24: Tests unitaires + E2E auth sur PostgreSQL réel et Mailpit.
A25: US-W01 | B25: Story | C25: Lot 1 | D25: E01 | E25: E01 | F25: Version web — Authentification | G25: En tant qu'utilisateur web, je veux retrouver sur navigateur les fonctions « Authentification » de l'application mobile, afin de travailler depuis mon poste. Critères d'acceptation : • Mêmes règles et mêmes API que la version mobile (aucune logique métier dupliquée). • Affichage correct sur Chrome, Edge, Safari, Firefox (2 dernières versions), de 1280 px à la tablette. • Critères d'acceptation des stories mobiles de l'épic re-vérifiés sur le web. | H25: Front Web | I25: Front | J25: Youssef Feki | K25: =SUMIFS($K:$K,$E:$E,A25,$B:$B,"Sous-tâche") -> 1 | L25: 2 | M25: Highest | N25: S09 | O25: À valider | P25: Choix du mode d'authentification (comptes locaux / annuaire SIVO / SSO) | Q25: =IF(COUNTIFS($E:$E,A25,$B:$B,"Sous-tâche")=0,"To Do",IF(COUNTIFS($E:$E,A25,$B:$B,"Sous-tâche",$Q:$Q,"Done")=COUNTIFS($E:$E,A25,$B:$B,"Sous-tâche"),"Done",IF(COUNTIFS($E:$E,A25,$B:$B,"Sous-tâche",$Q:$Q,"To Do")=COUNTIFS($E:$E,A25,$B:$B,"Sous-tâche"),"To Do","In Progress"))) -> To Do | R25: L1 – Socle technique / Tâche 1
A26: US-W01-T1 | B26: Sous-tâche | C26: Lot 1 | D26: E01 | E26: US-W01 | F26: [Front Web] Écrans connexion / mot de passe oublié (web) | H26: Front Web | I26: Front | J26: Youssef Feki | K26: 1 | M26: Highest | N26: S09 | O26: À valider | Q26: To Do | R26: L1 – Socle technique / Tâche 1
A27: E02 | B27: Epic | C27: Lot 1 | D27: E02 | F27: Gestion des accès et des rôles | G27: Objectif : Contrôler ce que chaque profil peut consulter ou modifier. Réf. : L1 – Socle technique / Tâche 1 | K27: =SUMIFS($K:$K,$D:$D,A27,$B:$B,"Sous-tâche") -> 3 | L27: =SUMIFS($L:$L,$D:$D,A27,$B:$B,"Story") -> 6 | M27: Highest | P27: E01 | Q27: =IF(COUNTIFS($D:$D,A27,$B:$B,"Sous-tâche")=0,"To Do",IF(COUNTIFS($D:$D,A27,$B:$B,"Sous-tâche",$Q:$Q,"Done")=COUNTIFS($D:$D,A27,$B:$B,"Sous-tâche"),"Done",IF(COUNTIFS($D:$D,A27,$B:$B,"Sous-tâche",$Q:$Q,"To Do")=COUNTIFS($D:$D,A27,$B:$B,"Sous-tâche"),"To Do","In Progress"))) -> In Progress | R27: L1 – Socle technique / Tâche 1
A28: US-03 | B28: Story | C28: Lot 1 | D28: E02 | E28: E02 | F28: Matrice des rôles et contrôle d'accès | G28: En tant qu'administrateur SIVO, je veux attribuer un rôle à chaque utilisateur, afin que chacun n'accède qu'aux écrans et données autorisés. Critères d'acceptation : • La matrice rôles × permissions est validée par SIVO avant développement (DoR). • Étant donné un opticien, quand il appelle l'API d'un autre opticien, alors il reçoit 403. • Les menus et boutons non autorisés sont masqués côté front ET bloqués côté API. | H28: Front Mobile, Back | I28: Front, Back | J28: Ahmed Jmal | K28: =SUMIFS($K:$K,$E:$E,A28,$B:$B,"Sous-tâche") -> 2.5 | L28: 5 | M28: Highest | N28: S01 | O28: Mixte | P28: E01 | Q28: =IF(COUNTIFS($E:$E,A28,$B:$B,"Sous-tâche")=0,"To Do",IF(COUNTIFS($E:$E,A28,$B:$B,"Sous-tâche",$Q:$Q,"Done")=COUNTIFS($E:$E,A28,$B:$B,"Sous-tâche"),"Done",IF(COUNTIFS($E:$E,A28,$B:$B,"Sous-tâche",$Q:$Q,"To Do")=COUNTIFS($E:$E,A28,$B:$B,"Sous-tâche"),"To Do","In Progress"))) -> In Progress | R28: L1 – Socle technique / Tâche 1
A29: US-03-T1 | B29: Sous-tâche | C29: Lot 1 | D29: E02 | E29: US-03 | F29: [Back] Modèle RBAC : roles, permissions, user_roles | H29: Back | I29: Back | J29: Ahmed Jmal | K29: 0.5 | M29: Highest | N29: S01 | O29: Devis | Q29: In Progress | R29: L1 – Socle technique / Tâche 1 | S29: OPT-102, OPT-103 | T29: Profils OPTICIEN / VENDEUR (profileType) ; matrice permissions complète non faite.
A30: US-03-T2 | B30: Sous-tâche | C30: Lot 1 | D30: E02 | E30: US-03 | F30: [Back] Middleware d'autorisation + cloisonnement par opticien | H30: Back | I30: Back | J30: Ahmed Jmal | K30: 1 | M30: Highest | N30: S01 | O30: Devis | Q30: In Progress | R30: L1 – Socle technique / Tâche 1 | S30: OPT-103, OPT-207 | T30: JwtAccessGuard + OpticienOnlyGuard + isolation multi-tenant ; à étendre aux autres modules.
A31: US-03-T3 | B31: Sous-tâche | C31: Lot 1 | D31: E02 | E31: US-03 | F31: [Front Mobile] Guards de routes et masquage conditionnel des actions | H31: Front Mobile | I31: Front | J31: Youssef Feki | K31: 0.5 | M31: Highest | N31: S01 | O31: Devis | Q31: In Progress | R31: L1 – Socle technique / Tâche 1 | S31: Rapport Front §3E | T31: Distinction OPTICIEN / VENDEUR à l'accueil ; masquage des actions à faire quand les écrans métier existeront.
A32: US-03-T4 | B32: Sous-tâche | C32: Lot 1 | D32: E02 | E32: US-03 | F32: [Back] Rôles Vendeur et Commercial dans la matrice RBAC | H32: Back | I32: Back | J32: Ahmed Jmal | K32: 0.5 | M32: Highest | N32: S01 | O32: À valider | Q32: In Progress | R32: L1 – Socle technique / Tâche 1 | S32: OPT-201..207 | T32: Rôle Vendeur fait ; rôle Commercial à faire.
A33: US-W02 | B33: Story | C33: Lot 1 | D33: E02 | E33: E02 | F33: Version web — Gestion des accès et des rôles | G33: En tant qu'utilisateur web, je veux retrouver sur navigateur les fonctions « Gestion des accès et des rôles » de l'application mobile, afin de travailler depuis mon poste. Critères d'acceptation : • Mêmes règles et mêmes API que la version mobile (aucune logique métier dupliquée). • Affichage correct sur Chrome, Edge, Safari, Firefox (2 dernières versions), de 1280 px à la tablette. • Critères d'acceptation des stories mobiles de l'épic re-vérifiés sur le web. | H33: Front Web | I33: Front | J33: Youssef Feki | K33: =SUMIFS($K:$K,$E:$E,A33,$B:$B,"Sous-tâche") -> 0.5 | L33: 1 | M33: Highest | N33: S09 | O33: À valider | P33: E01 | Q33: =IF(COUNTIFS($E:$E,A33,$B:$B,"Sous-tâche")=0,"To Do",IF(COUNTIFS($E:$E,A33,$B:$B,"Sous-tâche",$Q:$Q,"Done")=COUNTIFS($E:$E,A33,$B:$B,"Sous-tâche"),"Done",IF(COUNTIFS($E:$E,A33,$B:$B,"Sous-tâche",$Q:$Q,"To Do")=COUNTIFS($E:$E,A33,$B:$B,"Sous-tâche"),"To Do","In Progress"))) -> To Do | R33: L1 – Socle technique / Tâche 1
A34: US-W02-T1 | B34: Sous-tâche | C34: Lot 1 | D34: E02 | E34: US-W02 | F34: [Front Web] Guards de routes et masquage des actions (web) | H34: Front Web | I34: Front | J34: Youssef Feki | K34: 0.5 | M34: Highest | N34: S09 | O34: À valider | Q34: To Do | R34: L1 – Socle technique / Tâche 1
A35: E03 | B35: Epic | C35: Lot 1 | D35: E03 | F35: Base de données partagée & intégration SIVO | G35: Objectif : Partager les données avec l'IT SIVO et rester cohérent avec le système de production Oracle existant. Réf. : L1 – Socle technique / Tâche 1 | K35: =SUMIFS($K:$K,$D:$D,A35,$B:$B,"Sous-tâche") -> 18 | L35: =SUMIFS($L:$L,$D:$D,A35,$B:$B,"Story") -> 36 | M35: Highest | P35: Accès réseau / base SIVO | Q35: =IF(COUNTIFS($D:$D,A35,$B:$B,"Sous-tâche")=0,"To Do",IF(COUNTIFS($D:$D,A35,$B:$B,"Sous-tâche",$Q:$Q,"Done")=COUNTIFS($D:$D,A35,$B:$B,"Sous-tâche"),"Done",IF(COUNTIFS($D:$D,A35,$B:$B,"Sous-tâche",$Q:$Q,"To Do")=COUNTIFS($D:$D,A35,$B:$B,"Sous-tâche"),"To Do","In Progress"))) -> In Progress | R35: L1 – Socle technique / Tâche 1
A36: US-04 | B36: Story | C36: Lot 1 | D36: E03 | E36: E03 | F36: Modèle de données partagé | G36: En tant qu'équipe IT SIVO, je veux un modèle de données documenté avec ses propriétaires, afin de savoir qui écrit et qui lit chaque table. Critères d'acceptation : • MCD/MLD couvrant opticiens, produits, commandes, lignes, statuts, livraisons, réclamations. • Chaque table a un propriétaire (Projet / SIVO) et un mode d'accès (R / RW) validés en atelier. • Le dictionnaire de données est publié et versionné. | H36: Back | I36: Back | J36: Ahmed Jmal | K36: =SUMIFS($K:$K,$E:$E,A36,$B:$B,"Sous-tâche") -> 6 | L36: 13 | M36: Highest | N36: S01 | O36: Devis | P36: Accès réseau / base SIVO | Q36: =IF(COUNTIFS($E:$E,A36,$B:$B,"Sous-tâche")=0,"To Do",IF(COUNTIFS($E:$E,A36,$B:$B,"Sous-tâche",$Q:$Q,"Done")=COUNTIFS($E:$E,A36,$B:$B,"Sous-tâche"),"Done",IF(COUNTIFS($E:$E,A36,$B:$B,"Sous-tâche",$Q:$Q,"To Do")=COUNTIFS($E:$E,A36,$B:$B,"Sous-tâche"),"To Do","In Progress"))) -> In Progress | R36: L1 – Socle technique / Tâche 1
A37: US-04-T1 | B37: Sous-tâche | C37: Lot 1 | D37: E03 | E37: US-04 | F37: [Back] Conception MCD / MLD et conventions de nommage | H37: Back | I37: Back | J37: Ahmed Jmal | K37: 3 | M37: Highest | N37: S01 | O37: Devis | Q37: In Progress | R37: L1 – Socle technique / Tâche 1 | S37: OPT-101, OPT-201..203 | T37: Modèle auth / opticien / vendeur / site / planning en place ; commandes, précal, réclamations à modéliser et à valider avec l'IT SIVO.
A38: US-04-T2 | B38: Sous-tâche | C38: Lot 1 | D38: E03 | E38: US-04 | F38: [Back] Dictionnaire de données + matrice de responsabilités | H38: Back | I38: Back | J38: Ahmed Jmal | K38: 1 | M38: Highest | N38: S01 | O38: Devis | Q38: To Do | R38: L1 – Socle technique / Tâche 1
A39: US-04-T3 | B39: Sous-tâche | C39: Lot 1 | D39: E03 | E39: US-04 | F39: [Back] Mapping ORM des entités et repositories | H39: Back | I39: Back | J39: Ahmed Jmal | K39: 2 | M39: Highest | N39: S01 | O39: Devis | Q39: In Progress | R39: L1 – Socle technique / Tâche 1 | S39: OPT-101 | T39: Prisma 7 pour les entités existantes.
A40: US-05 | B40: Story | C40: Lot 1 | D40: E03 | E40: E03 | F40: Connexion sécurisée au SI SIVO (Oracle) | G40: En tant qu'équipe IT SIVO, je veux que l'application accède à nos données via des comptes de service à droits minimaux, afin de garder le contrôle de notre SI. Critères d'acceptation : • Connexion chiffrée (TLS) avec un compte de service par environnement. • Les droits sont limités aux tables listées dans la matrice US-04. • La synchronisation du catalogue SIVO tourne et ses erreurs sont journalisées. | H40: Back, DevOps | I40: Back, DevOps | J40: Ahmed Jmal | K40: =SUMIFS($K:$K,$E:$E,A40,$B:$B,"Sous-tâche") -> 6 | L40: 13 | M40: Highest | N40: S02 | O40: Devis | P40: Accès réseau / base SIVO | Q40: =IF(COUNTIFS($E:$E,A40,$B:$B,"Sous-tâche")=0,"To Do",IF(COUNTIFS($E:$E,A40,$B:$B,"Sous-tâche",$Q:$Q,"Done")=COUNTIFS($E:$E,A40,$B:$B,"Sous-tâche"),"Done",IF(COUNTIFS($E:$E,A40,$B:$B,"Sous-tâche",$Q:$Q,"To Do")=COUNTIFS($E:$E,A40,$B:$B,"Sous-tâche"),"To Do","In Progress"))) -> In Progress | R40: L1 – Socle technique / Tâche 1
...

Sheet Tâches par personne
A1: Vue d'affectation — une section par personne, triée par sprint
A3: Développeur | B3: Rôle | C3: Sprint | D3: Clé | E3: Story | F3: Tâche | G3: J/H | H3: Lot | I3: Source | J3: Priorité
A4: Youssef Feki | B4: Front Mobile | C4: S01 | D4: US-01-T2 | E4: US-01 – Connexion / déconnexion sécurisée | F4: Écran de connexion mobile + gestion du jeton et redirections | G4: 1 | H4: Lot 1 | I4: Devis | J4: Highest
A5: Youssef Feki | B5: Front Mobile | C5: S01 | D5: US-02-T2 | E5: US-02 – Mot de passe oublié & réinitialisation | F5: Écrans mot de passe oublié / nouveau mot de passe | G5: 0.5 | H5: Lot 1 | I5: Devis | J5: High
A6: Youssef Feki | B6: Front Mobile | C6: S01 | D6: US-03-T3 | E6: US-03 – Matrice des rôles et contrôle d'accès | F6: Guards de routes et masquage conditionnel des actions | G6: 0.5 | H6: Lot 1 | I6: Devis | J6: Highest
